<?xml version="1.0" encoding="utf-8"?>
<!-- This URDF was automatically created by SolidWorks to URDF Exporter! Originally created by Stephen Brawner (brawner@gmail.com) 
     Commit Version: 1.6.0-4-g7f85cfe  Build Version: 1.6.7995.38578
     For more information, please see http://wiki.ros.org/sw_urdf_exporter -->
<robot
  name="claw">
  <link
    name="base_link">
    <inertial>
      <origin
        xyz="0.0035472 -0.015685 0.00012867"
        rpy="0 0 0" />
      <mass
        value="5" />
      <inertia
        ixx="0.0031694"
        ixy="-6.3109E-06"
        ixz="-1.7238E-07"
        iyy="0.010685"
        iyz="1.0915E-07"
        izz="0.009926" />
    </inertial>
    <visual>
      <origin
        xyz="0 0 0"
        rpy="1.5707 0 1.5707" />
      <geometry>
        <mesh
          filename="package://claw/meshes/base_link.dae" />
      </geometry>
      <material
        name="">
        <color
          rgba="0.75294 0.75294 0.75294 1" />
      </material>
    </visual>
    <collision>
      <origin
        xyz="0 0 0"
        rpy="0 0 0" />
      <geometry>
        <mesh
          filename="package://claw/meshes/base_link.STL" />
      </geometry>
    </collision>
  </link>
  <link
    name="hip1">
    <inertial>
      <origin
        xyz="-0.023449 -0.012102 0.12134"
        rpy="0 0 0" />
      <mass
        value="1" />
      <inertia
        ixx="0.00038685"
        ixy="-1.3557E-05"
        ixz="-2.6501E-06"
        iyy="0.00040347"
        iyz="2.7091E-05"
        izz="0.00035185" />
    </inertial>
    <visual>
      <origin
        xyz="0 0 0"
        rpy="0 0 0" />
      <geometry>
        <mesh
          filename="package://claw/meshes/hip1.dae" />
      </geometry>
      <material
        name="">
        <color
          rgba="0.75294 0.75294 0.75294 1" />
      </material>
    </visual>
    <collision>
      <origin
        xyz="0 0 0"
        rpy="0 0 0" />
      <geometry>
        <mesh
          filename="package://claw/meshes/hip1.STL" />
      </geometry>
    </collision>
  </link>
  <joint
    name="HA1"
    type="continuous">
    <origin
      xyz="0.0645 0.1407 -0.030524"
      rpy="0 1.5708 0" />
    <parent
      link="base_link" />
    <child
      link="hip1" />
    <axis
      xyz="0 0 1" />
  </joint>
  <link
    name="leg1_link1">
    <inertial>
      <origin
        xyz="0.081078 -5.4044E-05 0.010528"
        rpy="0 0 0" />
      <mass
        value="1.5" />
      <inertia
        ixx="0.00016951"
        ixy="-3.6625E-05"
        ixz="3.3507E-07"
        iyy="0.0011555"
        iyz="5.0545E-08"
        izz="0.0013025" />
    </inertial>
    <visual>
      <origin
        xyz="0 0 0"
        rpy="0 0 0" />
      <geometry>
        <mesh
          filename="package://claw/meshes/leg1_link1.dae" />
      </geometry>
      <material
        name="">
        <color
          rgba="0.75294 0.75294 0.75294 1" />
      </material>
    </visual>
    <collision>
      <origin
        xyz="0 0 0"
        rpy="0 0 0" />
      <geometry>
        <mesh
          filename="package://claw/meshes/leg1_link1.STL" />
      </geometry>
    </collision>
  </link>
  <joint
    name="HF1"
    type="continuous">
    <origin
      xyz="0.0361733752673749 0 0.173825001007693"
      rpy="-1.5707963267949 0 0" />
    <parent
      link="hip1" />
    <child
      link="leg1_link1" />
    <axis
      xyz="0 0 1" />
  </joint>
  <link
    name="leg1_link2">
    <inertial>
      <origin
        xyz="0.062745 0.00028101 0.0091689"
        rpy="0 0 0" />
      <mass
        value="0.3" />
      <inertia
        ixx="2.4886E-05"
        ixy="4.039E-07"
        ixz="-5.3837E-08"
        iyy="8.2423E-05"
        iyz="-2.8631E-08"
        izz="9.1326E-05" />
    </inertial>
    <visual>
      <origin
        xyz="0 0 0"
        rpy="0 0 0" />
      <geometry>
        <mesh
          filename="package://claw/meshes/leg1_link2.dae" />
      </geometry>
      <material
        name="">
        <color
          rgba="0.75294 0.75294 0.75294 1" />
      </material>
    </visual>
    <collision>
      <origin
        xyz="0 0 0"
        rpy="0 0 0" />
      <geometry>
        <mesh
          filename="package://claw/meshes/leg1_link2.STL" />
      </geometry>
    </collision>
  </link>
  <joint
    name="KF1"
    type="continuous">
    <origin
      xyz="0.2245 0 0"
      rpy="0 0 -0.0014246" />
    <parent
      link="leg1_link1" />
    <child
      link="leg1_link2" />
    <axis
      xyz="0 0 1" />
  </joint>
  <link
    name="hip2">
    <inertial>
      <origin
        xyz="-0.023416 0.01208 0.12041"
        rpy="0 0 0" />
      <mass
        value="1" />
      <inertia
        ixx="0.00038698"
        ixy="1.3536E-05"
        ixz="-2.6717E-06"
        iyy="0.00040367"
        iyz="-2.7103E-05"
        izz="0.00035209" />
    </inertial>
    <visual>
      <origin
        xyz="0 0 0"
        rpy="0 0 0" />
      <geometry>
        <mesh
          filename="package://claw/meshes/hip2.dae" />
      </geometry>
      <material
        name="">
        <color
          rgba="0.75294 0.75294 0.75294 1" />
      </material>
    </visual>
    <collision>
      <origin
        xyz="0 0 0"
        rpy="0 0 0" />
      <geometry>
        <mesh
          filename="package://claw/meshes/hip2.STL" />
      </geometry>
    </collision>
  </link>
  <joint
    name="HA2"
    type="continuous">
    <origin
      xyz="0.0654999999999997 -0.140699273206225 -0.0305242368205386"
      rpy="0 1.5707963267949 0" />
    <parent
      link="base_link" />
    <child
      link="hip2" />
    <axis
      xyz="0 0 1" />
  </joint>
  <link
    name="leg2_link1">
    <inertial>
      <origin
        xyz="0.081078 -5.1327E-05 -0.010528"
        rpy="0 0 0" />
      <mass
        value="1.5" />
      <inertia
        ixx="0.00016951"
        ixy="-3.6626E-05"
        ixz="-3.3506E-07"
        iyy="0.0011555"
        iyz="-4.7415E-08"
        izz="0.0013025" />
    </inertial>
    <visual>
      <origin
        xyz="0 0 0"
        rpy="0 0 0" />
      <geometry>
        <mesh
          filename="package://claw/meshes/leg2_link1.dae" />
      </geometry>
      <material
        name="">
        <color
          rgba="0.75294 0.75294 0.75294 1" />
      </material>
    </visual>
    <collision>
      <origin
        xyz="0 0 0"
        rpy="0 0 0" />
      <geometry>
        <mesh
          filename="package://claw/meshes/leg2_link1.STL" />
      </geometry>
    </collision>
  </link>
  <joint
    name="HF2"
    type="continuous">
    <origin
      xyz="0.0361733752673847 0 0.172825001007691"
      rpy="-1.5707963267949 0 0" />
    <parent
      link="hip2" />
    <child
      link="leg2_link1" />
    <axis
      xyz="0 0 1" />
  </joint>
  <link
    name="leg2_link2">
    <inertial>
      <origin
        xyz="0.062744 0.00028101 -0.009169"
        rpy="0 0 0" />
      <mass
        value="0.3" />
      <inertia
        ixx="2.4886E-05"
        ixy="4.039E-07"
        ixz="5.3766E-08"
        iyy="8.2423E-05"
        iyz="2.8771E-08"
        izz="9.1326E-05" />
    </inertial>
    <visual>
      <origin
        xyz="0 0 0"
        rpy="0 0 0" />
      <geometry>
        <mesh
          filename="package://claw/meshes/leg2_link2.dae" />
      </geometry>
      <material
        name="">
        <color
          rgba="0.75294 0.75294 0.75294 1" />
      </material>
    </visual>
    <collision>
      <origin
        xyz="0 0 0"
        rpy="0 0 0" />
      <geometry>
        <mesh
          filename="package://claw/meshes/leg2_link2.STL" />
      </geometry>
    </collision>
  </link>
  <joint
    name="KF2"
    type="continuous">
    <origin
      xyz="0.22449657290337 0 0"
      rpy="0 0 -0.00142456498764465" />
    <parent
      link="leg2_link1" />
    <child
      link="leg2_link2" />
    <axis
      xyz="0 0 1" />
  </joint>
  <link
    name="hip3">
    <inertial>
      <origin
        xyz="-0.023415 0.012095 -0.1106"
        rpy="0 0 0" />
      <mass
        value="1" />
      <inertia
        ixx="0.00038695"
        ixy="1.355E-05"
        ixz="-3.9215E-05"
        iyy="0.00040367"
        iyz="2.8393E-05"
        izz="0.00035212" />
    </inertial>
    <visual>
      <origin
        xyz="0 0 0"
        rpy="0 0 0" />
      <geometry>
        <mesh
          filename="package://claw/meshes/hip3.dae" />
      </geometry>
      <material
        name="">
        <color
          rgba="0.75294 0.75294 0.75294 1" />
      </material>
    </visual>
    <collision>
      <origin
        xyz="0 0 0"
        rpy="0 0 0" />
      <geometry>
        <mesh
          filename="package://claw/meshes/hip3.STL" />
      </geometry>
    </collision>
  </link>
  <joint
    name="HA3"
    type="continuous">
    <origin
      xyz="-0.0655000000000001 -0.140699273206226 -0.0305242368205381"
      rpy="0 1.5707963267949 0" />
    <parent
      link="base_link" />
    <child
      link="hip3" />
    <axis
      xyz="0 0 1" />
  </joint>
  <link
    name="leg3_link1">
    <inertial>
      <origin
        xyz="0.081078 -5.1327E-05 -0.010528"
        rpy="0 0 0" />
      <mass
        value="1.5" />
      <inertia
        ixx="0.00016951"
        ixy="-3.6626E-05"
        ixz="-3.3506E-07"
        iyy="0.0011555"
        iyz="-4.7415E-08"
        izz="0.0013025" />
    </inertial>
    <visual>
      <origin
        xyz="0 0 0"
        rpy="0 0 0" />
      <geometry>
        <mesh
          filename="package://claw/meshes/leg3_link1.dae" />
      </geometry>
      <material
        name="">
        <color
          rgba="0.75294 0.75294 0.75294 1" />
      </material>
    </visual>
    <collision>
      <origin
        xyz="0 0 0"
        rpy="0 0 0" />
      <geometry>
        <mesh
          filename="package://claw/meshes/leg3_link1.STL" />
      </geometry>
    </collision>
  </link>
  <joint
    name="HF3"
    type="continuous">
    <origin
      xyz="0.0361733752673756 0 -0.116174998992309"
      rpy="-1.5707963267949 0 0" />
    <parent
      link="hip3" />
    <child
      link="leg3_link1" />
    <axis
      xyz="0 0 1" />
  </joint>
  <link
    name="leg3_link2">
    <inertial>
      <origin
        xyz="0.062744 0.00028101 -0.009169"
        rpy="0 0 0" />
      <mass
        value="0.3" />
      <inertia
        ixx="2.4886E-05"
        ixy="4.039E-07"
        ixz="5.3766E-08"
        iyy="8.2423E-05"
        iyz="2.8771E-08"
        izz="9.1326E-05" />
    </inertial>
    <visual>
      <origin
        xyz="0 0 0"
        rpy="0 0 0" />
      <geometry>
        <mesh
          filename="package://claw/meshes/leg3_link2.dae" />
      </geometry>
      <material
        name="">
        <color
          rgba="0.75294 0.75294 0.75294 1" />
      </material>
    </visual>
    <collision>
      <origin
        xyz="0 0 0"
        rpy="0 0 0" />
      <geometry>
        <mesh
          filename="package://claw/meshes/leg3_link2.STL" />
      </geometry>
    </collision>
  </link>
  <joint
    name="KF3"
    type="continuous">
    <origin
      xyz="0.22449657290337 0 0"
      rpy="0 0 -0.00013038185156131" />
    <parent
      link="leg3_link1" />
    <child
      link="leg3_link2" />
    <axis
      xyz="0 0 1" />
  </joint>
  <link
    name="hip4">
    <inertial>
      <origin
        xyz="-0.02344 -0.012117 -0.11057"
        rpy="0 0 0" />
      <mass
        value="1" />
      <inertia
        ixx="0.00038684"
        ixy="-1.3565E-05"
        ixz="-3.9188E-05"
        iyy="0.00040347"
        iyz="-2.8419E-05"
        izz="0.00035187" />
    </inertial>
    <visual>
      <origin
        xyz="0 0 0"
        rpy="0 0 0" />
      <geometry>
        <mesh
          filename="package://claw/meshes/hip4.dae" />
      </geometry>
      <material
        name="">
        <color
          rgba="0.75294 0.75294 0.75294 1" />
      </material>
    </visual>
    <collision>
      <origin
        xyz="0 0 0"
        rpy="0 0 0" />
      <geometry>
        <mesh
          filename="package://claw/meshes/hip4.STL" />
      </geometry>
    </collision>
  </link>
  <joint
    name="HA4"
    type="continuous">
    <origin
      xyz="-0.0655 0.1407 -0.030524"
      rpy="0 1.5708 0" />
    <parent
      link="base_link" />
    <child
      link="hip4" />
    <axis
      xyz="0 0 1" />
  </joint>
  <link
    name="leg4_link1">
    <inertial>
      <origin
        xyz="0.081078 -5.4044E-05 0.010528"
        rpy="0 0 0" />
      <mass
        value="1.5" />
      <inertia
        ixx="0.00016951"
        ixy="-3.6625E-05"
        ixz="3.3507E-07"
        iyy="0.0011555"
        iyz="5.0545E-08"
        izz="0.0013025" />
    </inertial>
    <visual>
      <origin
        xyz="0 0 0"
        rpy="0 0 0" />
      <geometry>
        <mesh
          filename="package://claw/meshes/leg4_link1.dae" />
      </geometry>
      <material
        name="">
        <color
          rgba="0.75294 0.75294 0.75294 1" />
      </material>
    </visual>
    <collision>
      <origin
        xyz="0 0 0"
        rpy="0 0 0" />
      <geometry>
        <mesh
          filename="package://claw/meshes/leg4_link1.STL" />
      </geometry>
    </collision>
  </link>
  <joint
    name="HF4"
    type="continuous">
    <origin
      xyz="0.0361733752673765 0 -0.116174998992308"
      rpy="-1.5707963267949 0 0" />
    <parent
      link="hip4" />
    <child
      link="leg4_link1" />
    <axis
      xyz="0 0 1" />
  </joint>
  <link
    name="leg4_link2">
    <inertial>
      <origin
        xyz="0.062745 0.00028101 0.0091689"
        rpy="0 0 0" />
      <mass
        value="0.3" />
      <inertia
        ixx="2.4886E-05"
        ixy="4.039E-07"
        ixz="-5.3837E-08"
        iyy="8.2423E-05"
        iyz="-2.8631E-08"
        izz="9.1326E-05" />
    </inertial>
    <visual>
      <origin
        xyz="0 0 0"
        rpy="0 0 0" />
      <geometry>
        <mesh
          filename="package://claw/meshes/leg4_link2.dae" />
      </geometry>
      <material
        name="">
        <color
          rgba="0.75294 0.75294 0.75294 1" />
      </material>
    </visual>
    <collision>
      <origin
        xyz="0 0 0"
        rpy="0 0 0" />
      <geometry>
        <mesh
          filename="package://claw/meshes/leg4_link2.STL" />
      </geometry>
    </collision>
  </link>
  <joint
    name="KF4"
    type="continuous">
    <origin
      xyz="0.2245 0 0"
      rpy="0 0 -0.00013038" />
    <parent
      link="leg4_link1" />
    <child
      link="leg4_link2" />
    <axis
      xyz="0 0 1" />
  </joint>
</robot>